<sdf version='1.6'>
  <model name='two_bodies'>

  <link name="bottom">
  <pose> 0 0 0.025 0 0 0</pose>
  <visual name='bottom'>
    <geometry>
      <box>
       <size>0.25 0.25 0.05</size>
      </box>
    </geometry>
  </visual>

  <visual name='right_wall'>
    <pose> 0 0.115 0.14 0 0 0</pose>
    <geometry>
      <box>
       <size>0.25 0.02 0.23</size>
      </box>
    </geometry>
  </visual>

  <visual name='left_wall'>
    <pose> 0 -0.115 0.14 0 0 0</pose>
    <geometry>
      <box>
       <size>0.25 0.02 0.23</size>
      </box>
    </geometry>
  </visual>

  <collision name='bottom'>
    <geometry>
      <box>
       <size>0.249 0.249 0.049</size>
      </box>
    </geometry>
  </collision>

  <collision name='right_wall'>
    <pose> 0 0.115 0.14 0 0 0</pose>
    <geometry>
      <box>
       <size>0.249 0.019 0.229</size>
      </box>
    </geometry>
  </collision>

  <collision name='left_wall'>
    <pose> 0 -0.115 0.14 0 0 0</pose>
    <geometry>
      <box>
       <size>0.249 0.019 0.229</size>
      </box>
    </geometry>
  </collision>

  </link>

  <link name="top">
  <pose> 0 0 0.29 0 0 0</pose>

  <visual name='top'>
    <geometry>
      <box>
       <size>0.25 0.25 0.02</size>
      </box>
    </geometry>
  </visual>

  <collision name='top'>
    <geometry>
      <box>
       <size>0.249 0.249 0.019</size>
      </box>
    </geometry>
  </collision>
  </link>

  <!-- joint between bottom and top -->
  <joint name="bottom_top" type="fixed">
    <child>top</child>
    <parent>bottom</parent>
    <pose>0 0 0 0 0 0 </pose>
  </joint>

  <!-- joint between bottom and door -->
  <joint name="door_hinge" type="revolute">
    <child>door</child>
    <parent>bottom</parent>
    <pose>0 0 -0.125 0 0 0 </pose>
    <axis>
      <xyz> 0 1 0 </xyz>
      <dynamics>
        <damping>1.0</damping>
        <friction>1000.0</friction>
      </dynamics>
    </axis>
  </joint>

  <link name="door">
  <pose> 0.125 0 0.175 0 0 0</pose>
  <inertial>
      <mass>1</mass>
      <inertia>
        <ixx>0.01042</ixx>
        <ixy>0</ixy>
        <ixz>0</ixz>
        <iyy>0.00542</iyy>
        <iyz>0</iyz>
        <izz>0.00542</izz>
      </inertia>
  </inertial>

  <visual name='cylinder'>
    <pose> 0.06 0 0.075 1.5708 0 0</pose>
    <geometry>
      <cylinder> 
        <length>0.15</length>
        <radius>0.01</radius>
      </cylinder>
    </geometry>
  </visual>

  <visual name='slab'>
    <pose> 0.01 0 0 0 0 0</pose>
    <geometry>
      <box>
       <size>0.02 0.25 0.25</size>
      </box>
    </geometry>

    <material>
      <diffuse>1 0 0 0.9</diffuse>
    </material>
  </visual>

  <collision name='cylinder'>
    <pose> 0.06 0 0.075 1.5708 0 0</pose>
    <geometry>
      <cylinder> 
        <length>0.149</length>
        <radius>0.0099</radius>
      </cylinder>
    </geometry>
  </collision>

  <collision name='slab'>
    <pose> 0.01 0 0 0 0 0</pose>
    <geometry>
      <box>
       <size>0.019 0.249 0.249</size>
      </box>
    </geometry>
  </collision>
  </link>


  </model>
</sdf>



